[32m2023-05-27 10:10:48 -0400[0m - dagster - [34mDEBUG[0m - __ASSET_JOB - 9b932126-473d-492f-9fdb-9e156c4ff6f5 - 44186 - LOGS_CAPTURED - Started capturing logs in process (pid: 44186).
[32m2023-05-27 10:10:48 -0400[0m - dagster - [34mDEBUG[0m - __ASSET_JOB - 9b932126-473d-492f-9fdb-9e156c4ff6f5 - 44186 - vitals__power_bi__el_paso - STEP_START - Started execution of step "vitals__power_bi__el_paso".
[32m2023-05-27 10:10:48 -0400[0m - dagster - [34mERROR[0m - [31m__ASSET_JOB - 9b932126-473d-492f-9fdb-9e156c4ff6f5 - 44186 - vitals__power_bi__el_paso - STEP_FAILURE - Execution of step "vitals__power_bi__el_paso" failed.

dagster._core.errors.DagsterExecutionStepExecutionError: Error occurred while executing op "vitals__power_bi__el_paso"::

KeyError: 'el_paso'

Stack Trace:
  File "/Users/jeffb/mambaforge/envs/covid/lib/python3.11/site-packages/dagster/_core/execution/plan/utils.py", line 54, in op_execution_error_boundary
    yield
  File "/Users/jeffb/mambaforge/envs/covid/lib/python3.11/site-packages/dagster/_utils/__init__.py", line 445, in iterate_with_context
    next_output = next(iterator)
                  ^^^^^^^^^^^^^^
  File "/Users/jeffb/mambaforge/envs/covid/lib/python3.11/site-packages/dagster/_core/execution/plan/compute_generator.py", line 124, in _coerce_op_compute_fn_to_iterator
    result = invoke_compute_fn(
             ^^^^^^^^^^^^^^^^^^
  File "/Users/jeffb/mambaforge/envs/covid/lib/python3.11/site-packages/dagster/_core/execution/plan/compute_generator.py", line 118, in invoke_compute_fn
    return fn(context, **args_to_pass) if context_arg_provided else fn(**args_to_pass)
                                                                    ^^^^^^^^^^^^^^^^^^
  File "/Users/jeffb/Desktop/Life/personal-projects/COVID/etl/assets/vitals/get_power_bi.py", line 54, in get_vitals_el_paso
    return get_vitals(POWER_BI_CONFIG['el_paso'])
                      ~~~~~~~~~~~~~~~^^^^^^^^^^^
[0m
