[32m2023-05-27 10:29:23 -0400[0m - dagster - [34mDEBUG[0m - __ASSET_JOB - 2bd4124b-560c-4d5c-8338-e7cfbf909ee0 - 46625 - LOGS_CAPTURED - Started capturing logs in process (pid: 46625).
[32m2023-05-27 10:29:23 -0400[0m - dagster - [34mDEBUG[0m - __ASSET_JOB - 2bd4124b-560c-4d5c-8338-e7cfbf909ee0 - 46625 - wastewater__cdc__cdc_wastewater - STEP_START - Started execution of step "wastewater__cdc__cdc_wastewater".
[32m2023-05-27 10:29:23 -0400[0m - dagster - [34mERROR[0m - [31m__ASSET_JOB - 2bd4124b-560c-4d5c-8338-e7cfbf909ee0 - 46625 - wastewater__cdc__cdc_wastewater - STEP_FAILURE - Execution of step "wastewater__cdc__cdc_wastewater" failed.

dagster._core.errors.DagsterExecutionStepExecutionError: Error occurred while executing op "wastewater__cdc__cdc_wastewater"::

KeyError: "['date_start'] not found in axis"

Stack Trace:
  File "/Users/jeffb/mambaforge/envs/covid/lib/python3.11/site-packages/dagster/_core/execution/plan/utils.py", line 54, in op_execution_error_boundary
    yield
  File "/Users/jeffb/mambaforge/envs/covid/lib/python3.11/site-packages/dagster/_utils/__init__.py", line 445, in iterate_with_context
    next_output = next(iterator)
                  ^^^^^^^^^^^^^^
  File "/Users/jeffb/mambaforge/envs/covid/lib/python3.11/site-packages/dagster/_core/execution/plan/compute_generator.py", line 124, in _coerce_op_compute_fn_to_iterator
    result = invoke_compute_fn(
             ^^^^^^^^^^^^^^^^^^
  File "/Users/jeffb/mambaforge/envs/covid/lib/python3.11/site-packages/dagster/_core/execution/plan/compute_generator.py", line 118, in invoke_compute_fn
    return fn(context, **args_to_pass) if context_arg_provided else fn(**args_to_pass)
                                                                    ^^^^^^^^^^^^^^^^^^
  File "/Users/jeffb/Desktop/Life/personal-projects/COVID/etl/assets/wastewater/get_cdc_wastewater.py", line 38, in get_cdc_wastewater
    clean_df = clean_data(results_df)
               ^^^^^^^^^^^^^^^^^^^^^^
  File "/Users/jeffb/Desktop/Life/personal-projects/COVID/src/wastewater/get_cdc_wastewater.py", line 74, in clean_data
    formatted_df = format_raw_data(df)
                   ^^^^^^^^^^^^^^^^^^^
  File "/Users/jeffb/Desktop/Life/personal-projects/COVID/src/wastewater/get_cdc_wastewater.py", line 43, in format_raw_data
    .drop(columns=['date_start'])
     ^^^^^^^^^^^^^^^^^^^^^^^^^^^^
  File "/Users/jeffb/mambaforge/envs/covid/lib/python3.11/site-packages/pandas/core/frame.py", line 5268, in drop
    return super().drop(
           ^^^^^^^^^^^^^
  File "/Users/jeffb/mambaforge/envs/covid/lib/python3.11/site-packages/pandas/core/generic.py", line 4549, in drop
    obj = obj._drop_axis(labels, axis, level=level, errors=errors)
          ^^^^^^^^^^^^^^^^^^^^^^^^^^^^^^^^^^^^^^^^^^^^^^^^^^^^^^^^
  File "/Users/jeffb/mambaforge/envs/covid/lib/python3.11/site-packages/pandas/core/generic.py", line 4591, in _drop_axis
    new_axis = axis.drop(labels, errors=errors)
               ^^^^^^^^^^^^^^^^^^^^^^^^^^^^^^^^
  File "/Users/jeffb/mambaforge/envs/covid/lib/python3.11/site-packages/pandas/core/indexes/base.py", line 6696, in drop
    raise KeyError(f"{list(labels[mask])} not found in axis")
[0m
